<!-- Cheetah Model
    The state space is populated with joints in the order that they are
    defined in this file. The actuators also operate on joints.
    State-Space (name/joint/parameter):
        - rootx     slider      position (m)
        - rootz     slider      position (m)
        - rooty     hinge       angle (rad)
        - bthigh    hinge       angle (rad)
        - bshin     hinge       angle (rad)
        - bfoot     hinge       angle (rad)
        - fthigh    hinge       angle (rad)
        - fshin     hinge       angle (rad)
        - ffoot     hinge       angle (rad)
        - rootx     slider      velocity (m/s)
        - rootz     slider      velocity (m/s)
        - rooty     hinge       angular velocity (rad/s)
        - bthigh    hinge       angular velocity (rad/s)
        - bshin     hinge       angular velocity (rad/s)
        - bfoot     hinge       angular velocity (rad/s)
        - fthigh    hinge       angular velocity (rad/s)
        - fshin     hinge       angular velocity (rad/s)
        - ffoot     hinge       angular velocity (rad/s)
    Actuators (name/actuator/parameter):
        - bthigh    hinge       torque (N m)
        - bshin     hinge       torque (N m)
        - bfoot     hinge       torque (N m)
        - fthigh    hinge       torque (N m)
        - fshin     hinge       torque (N m)
        - ffoot     hinge       torque (N m)
-->
<mujoco model="cheetah">
  <compiler angle="radian" coordinate="local" inertiafromgeom="true" settotalmass="14"/>
  <default>
    <joint armature=".1" damping=".01" limited="true" solimplimit="0 .8 .03" solreflimit=".02 1" stiffness="8"/>
    <geom conaffinity="0" condim="3" contype="1" friction="0.4 .1 .1" rgba="0.8 0.6 .4 1" solimp="0.0 0.8 0.01" solref="0.02 1"/>
    <motor ctrllimited="true" ctrlrange="-1 1"/>
  </default>
  <size nstack="300000" nuser_geom="1"/>
  <option gravity="0 0 -9.81" timestep="0.01"/>
  <worldbody>
    <body name="torso" pos="0 0 .7">
      <joint armature="0" axis="1 0 0" damping="0" limited="false" name="ignorex" pos="0 0 0" stiffness="0" type="slide"/>
      <joint armature="0" axis="0 0 1" damping="0" limited="false" name="ignorez" pos="0 0 0" stiffness="0" type="slide"/>
      <joint armature="0" axis="0 1 0" damping="0" limited="false" name="ignorey" pos="0 0 0" stiffness="0" type="hinge"/>
      <!-- CRAS14: torso mod />-->
      <geom name="torso" size=".25 .25 .04" type="box"/>
      <!--<geom axisangle="0 1 0 .87" name="head" pos=".6 0 .1" size="0.046 .15" type="capsule"/> />-->
      <!-- CRAS14: right back leg />-->
      <body name="bthigh" pos="-.25 -.30 0" euler="0 0 0">
        <joint axis="0 0 1" damping="6" name="bthigh" pos="0 0 0" range="-1.57 1.57" stiffness="240" type="hinge"/>
        <geom axisangle="0 0 1 0" name="bthigh" pos="0 0 0" size="0.046 .145" type="sphere"/>
        <body name="bshin" pos="0 -.1 0" euler="0 0 0">
          <joint axis="1 0 0" damping="4.5" name="bshin" pos="0 0 0" range="-.87 .87" stiffness="180" type="hinge"/>
          <geom axisangle="1 0 0 20.43" name="bshin" pos="0 -.04 0" rgba="0.9 0.6 0.6 1" size="0.046 .05" type="capsule"/>
          <body name="bfoot" pos="0 -.18 0">
            <joint axis="1 0 0" damping="3" name="bfoot" pos="0 0 0" range="-1.57 1.57" stiffness="240" type="hinge"/>
            <geom axisangle="0 1 0 0" name="bfoot" pos="0 0 -.10" rgba="0.9 0.6 0.6 1" size="0.046 .10" type="capsule"/>
          </body>
        </body>
      </body>
      <!-- CRAS14: front leg />-->
      <body name="fthigh" pos=".25 .3 0">
        <joint axis="0 0 1" damping="6" name="fthigh" pos="0 0 0" range="-1.57 1.57" stiffness="240" type="hinge"/>
        <geom axisangle="0 0 1 0" name="fthigh" pos="0 0 0" size="0.046 .145" type="sphere"/>
        <body name="fshin" pos="0 .1 0">
          <joint axis="1 0 0" damping="4.5" name="fshin" pos="0 0 0" range="-1.57 1.57" stiffness="240" type="hinge"/>
          <geom axisangle="1 0 0 20.43" name="fshin" pos="0 .04 0" rgba="0.9 0.6 0.6 1" size="0.046 .05" type="capsule"/>
          <body name="ffoot" pos="0 .18 0">
            <joint axis="1 0 0" damping="3" name="ffoot" pos="0 0 0" range="-1.57 1.57" stiffness="240" type="hinge"/>
            <geom axisangle="0 1 0 0" name="ffoot" pos="0 0 -.10" rgba="0.9 0.6 0.6 1" size="0.046 .10" type="capsule"/>
          </body>
        </body>
      </body>
      <!-- CRAS14: back leg1 />-->
      <body name="bthigh1" pos="-.25 .30 0">
        <joint axis="0 0 1" damping="6" name="bthigh1" pos="0 0 0" range="-1.57 1.57" stiffness="240" type="hinge"/>
        <geom axisangle="0 0 1 0" name="bthigh1" pos="0 0 0" size="0.046 .145" type="sphere"/>
        <body name="bshin1" pos="0 .1 0">
          <joint axis="1 0 0" damping="4.5" name="bshin1" pos="0 0 0" range="-.87 .87" stiffness="180" type="hinge"/>
          <geom axisangle="1 0 0 20.43" name="bshin1" pos="0 .04 0" rgba="0.9 0.6 0.6 1" size="0.046 .05" type="capsule"/>
          <body name="bfoot1" pos="0 .18 0">
            <joint  axis="1 0 0" damping="3" name="bfoot1" pos="0 0 0" range="-1.57 1.57" stiffness="240" type="hinge"/>
            <geom axisangle="0 1 0 0" name="bfoot1" pos="0 0 -.10" rgba="0.9 0.6 0.6 1" size="0.046 .10" type="capsule"/>
          </body>
        </body>
      </body>
      <!-- CRAS14: front leg1 />-->
      <body name="fthigh1" pos=".25 -.3 0">
        <joint axis="0 0 1" damping="6" name="fthigh1" pos="0 0 0" range="-1.57 1.57" stiffness="240" type="hinge"/>
        <geom axisangle="0 0 1 0" name="fthigh1" pos="0 0 0" size="0.046 .145" type="sphere"/>
        <body name="fshin1" pos="0 -.1 0">
          <joint axis="1 0 0" damping="4.5" name="fshin1" pos="0 0 0" range="-1.57 1.57" stiffness="240" type="hinge"/>
          <geom axisangle="1 0 0 20.43" name="fshin1" pos="0 -.04 0" rgba="0.9 0.6 0.6 1" size="0.046 .05" type="capsule"/>
          <body name="ffoot1" pos="0 -.18 0">
            <joint axis="1 0 0" damping="3" name="ffoot1" pos="0 0 0" range="-1.57 1.57" stiffness="240" type="hinge"/>
            <geom axisangle="0 1 0 0" name="ffoot1" pos="0 0 -.10" rgba="0.9 0.6 0.6 1" size="0.046 .10" type="capsule"/>
          </body>
        </body>
      </body>
    </body>
  </worldbody>
  <actuator>
    <motor gear="60" joint="bthigh" name="bthigh"/>
    <motor gear="60" joint="bshin" name="bshin"/>
    <motor gear="60" joint="bfoot" name="bfoot"/>
    <motor gear="60" joint="fthigh" name="fthigh"/>
    <motor gear="60" joint="fshin" name="fshin"/>
    <motor gear="60" joint="ffoot" name="ffoot"/>
    <!-- extra legs/>-->
    <motor gear="60" joint="bthigh1" name="bthigh1"/>
    <motor gear="60" joint="bshin1" name="bshin1"/>
    <motor gear="60" joint="bfoot1" name="bfoot1"/>
    <motor gear="60" joint="fthigh1" name="fthigh1"/>
    <motor gear="60" joint="fshin1" name="fshin1"/>
    <motor gear="60" joint="ffoot1" name="ffoot1"/>
  </actuator>
</mujoco>
